<?xml version="1.0" ?>
<!-- =================================================================================== -->
<!-- |    This document was autogenerated by xacro from src/wheelchair_isaac/urdf/robot.xacro | -->
<!-- |    EDITING THIS FILE BY HAND IS NOT RECOMMENDED                                 | -->
<!-- =================================================================================== -->
<robot name="robot">
  <material name="silver">
    <color rgba="0.700 0.700 0.700 1.000"/>
  </material>
  <transmission name="base_to_link1_left_tran">
    <type>transmission_interface/SimpleTransmission</type>
    <joint name="base_to_link1_left">
      <hardwareInterface>hardware_interface/EffortJointInterface</hardwareInterface>
    </joint>
    <actuator name="base_to_link1_left_actr">
      <hardwareInterface>hardware_interface/EffortJointInterface</hardwareInterface>
      <mechanicalReduction>1</mechanicalReduction>
    </actuator>
  </transmission>
  <transmission name="link1_to_track_left_tran">
    <type>transmission_interface/SimpleTransmission</type>
    <joint name="link1_to_track_left">
      <hardwareInterface>hardware_interface/EffortJointInterface</hardwareInterface>
    </joint>
    <actuator name="link1_to_track_left_actr">
      <hardwareInterface>hardware_interface/EffortJointInterface</hardwareInterface>
      <mechanicalReduction>1</mechanicalReduction>
    </actuator>
  </transmission>
  <transmission name="wheel_left_tran">
    <type>transmission_interface/SimpleTransmission</type>
    <joint name="wheel_left">
      <hardwareInterface>hardware_interface/EffortJointInterface</hardwareInterface>
    </joint>
    <actuator name="wheel_left_actr">
      <hardwareInterface>hardware_interface/EffortJointInterface</hardwareInterface>
      <mechanicalReduction>1</mechanicalReduction>
    </actuator>
  </transmission>
  <transmission name="base_to_link2_left_tran">
    <type>transmission_interface/SimpleTransmission</type>
    <joint name="base_to_link2_left">
      <hardwareInterface>hardware_interface/EffortJointInterface</hardwareInterface>
    </joint>
    <actuator name="base_to_link2_left_actr">
      <hardwareInterface>hardware_interface/EffortJointInterface</hardwareInterface>
      <mechanicalReduction>1</mechanicalReduction>
    </actuator>
  </transmission>
  <transmission name="base_to_link1_right_tran">
    <type>transmission_interface/SimpleTransmission</type>
    <joint name="base_to_link1_right">
      <hardwareInterface>hardware_interface/EffortJointInterface</hardwareInterface>
    </joint>
    <actuator name="base_to_link1_right_actr">
      <hardwareInterface>hardware_interface/EffortJointInterface</hardwareInterface>
      <mechanicalReduction>1</mechanicalReduction>
    </actuator>
  </transmission>
  <transmission name="link1_to_track_right_tran">
    <type>transmission_interface/SimpleTransmission</type>
    <joint name="link1_to_track_right">
      <hardwareInterface>hardware_interface/EffortJointInterface</hardwareInterface>
    </joint>
    <actuator name="link1_to_track_right_actr">
      <hardwareInterface>hardware_interface/EffortJointInterface</hardwareInterface>
      <mechanicalReduction>1</mechanicalReduction>
    </actuator>
  </transmission>
  <transmission name="base_to_link2_right_tran">
    <type>transmission_interface/SimpleTransmission</type>
    <joint name="base_to_link2_right">
      <hardwareInterface>hardware_interface/EffortJointInterface</hardwareInterface>
    </joint>
    <actuator name="base_to_link2_right_actr">
      <hardwareInterface>hardware_interface/EffortJointInterface</hardwareInterface>
      <mechanicalReduction>1</mechanicalReduction>
    </actuator>
  </transmission>
  <transmission name="wheel_right_tran">
    <type>transmission_interface/SimpleTransmission</type>
    <joint name="wheel_right">
      <hardwareInterface>hardware_interface/EffortJointInterface</hardwareInterface>
    </joint>
    <actuator name="wheel_right_actr">
      <hardwareInterface>hardware_interface/EffortJointInterface</hardwareInterface>
      <mechanicalReduction>1</mechanicalReduction>
    </actuator>
  </transmission>
  <transmission name="base_to_backSeat_tran">
    <type>transmission_interface/SimpleTransmission</type>
    <joint name="base_to_backSeat">
      <hardwareInterface>hardware_interface/EffortJointInterface</hardwareInterface>
    </joint>
    <actuator name="base_to_backSeat_actr">
      <hardwareInterface>hardware_interface/EffortJointInterface</hardwareInterface>
      <mechanicalReduction>1</mechanicalReduction>
    </actuator>
  </transmission>
  <transmission name="Revolute 38_tran">
    <type>transmission_interface/SimpleTransmission</type>
    <joint name="Revolute 38">
      <hardwareInterface>hardware_interface/EffortJointInterface</hardwareInterface>
    </joint>
    <actuator name="Revolute 38_actr">
      <hardwareInterface>hardware_interface/EffortJointInterface</hardwareInterface>
      <mechanicalReduction>1</mechanicalReduction>
    </actuator>
  </transmission>
  <transmission name="Revolute 39_tran">
    <type>transmission_interface/SimpleTransmission</type>
    <joint name="Revolute 39">
      <hardwareInterface>hardware_interface/EffortJointInterface</hardwareInterface>
    </joint>
    <actuator name="Revolute 39_actr">
      <hardwareInterface>hardware_interface/EffortJointInterface</hardwareInterface>
      <mechanicalReduction>1</mechanicalReduction>
    </actuator>
  </transmission>
  <gazebo>
    <plugin filename="gz_ros2_control-system" name="gz_ros2_control::GazeboSimROS2ControlPlugin"/>
  </gazebo>
  <gazebo reference="base_link">
    <material>Gazebo/Silver</material>
    <mu1>0.2</mu1>
    <mu2>0.2</mu2>
    <self_collide>true</self_collide>
    <gravity>true</gravity>
  </gazebo>
  <gazebo reference="link_1_1">
    <material>Gazebo/Silver</material>
    <mu1>0.2</mu1>
    <mu2>0.2</mu2>
    <self_collide>true</self_collide>
  </gazebo>
  <gazebo reference="track_left_1">
    <material>Gazebo/Silver</material>
    <mu1>0.2</mu1>
    <mu2>0.2</mu2>
    <self_collide>true</self_collide>
  </gazebo>
  <gazebo reference="left_wheel_1">
    <material>Gazebo/Silver</material>
    <mu1>0.2</mu1>
    <mu2>0.2</mu2>
    <self_collide>true</self_collide>
  </gazebo>
  <gazebo reference="link_2_1">
    <material>Gazebo/Silver</material>
    <mu1>0.2</mu1>
    <mu2>0.2</mu2>
    <self_collide>true</self_collide>
  </gazebo>
  <gazebo reference="link_1_right_1">
    <material>Gazebo/Silver</material>
    <mu1>0.2</mu1>
    <mu2>0.2</mu2>
    <self_collide>true</self_collide>
  </gazebo>
  <gazebo reference="track_right_1">
    <material>Gazebo/Silver</material>
    <mu1>0.2</mu1>
    <mu2>0.2</mu2>
    <self_collide>true</self_collide>
  </gazebo>
  <gazebo reference="link_2_right_1">
    <material>Gazebo/Silver</material>
    <mu1>0.2</mu1>
    <mu2>0.2</mu2>
    <self_collide>true</self_collide>
  </gazebo>
  <gazebo reference="right_wheel_1">
    <material>Gazebo/Silver</material>
    <mu1>0.2</mu1>
    <mu2>0.2</mu2>
    <self_collide>true</self_collide>
  </gazebo>
  <gazebo reference="back_seat_1">
    <material>Gazebo/Silver</material>
    <mu1>0.2</mu1>
    <mu2>0.2</mu2>
    <self_collide>true</self_collide>
  </gazebo>
  <gazebo reference="track_left_1">
    <material>Gazebo/Silver</material>
    <mu1>0.2</mu1>
    <mu2>0.2</mu2>
    <self_collide>true</self_collide>
  </gazebo>
  <gazebo reference="track_right_1">
    <material>Gazebo/Silver</material>
    <mu1>0.2</mu1>
    <mu2>0.2</mu2>
    <self_collide>true</self_collide>
  </gazebo>
  <link name="base_footprint"/>
  <link name="base_link">
    <inertial>
      <origin rpy="0 0 0" xyz="4.216737006355157e-05 0.14539775015650658 0.001317145519381857"/>
      <mass value="5.68537979998827"/>
      <inertia ixx="0.122934" ixy="-3.1e-05" ixz="6e-06" iyy="0.179358" iyz="0.016444" izz="0.285612"/>
    </inertial>
    <visual>
      <origin rpy="0 0 0" xyz="0 0 0"/>
      <geometry>
        <mesh filename="file:///home/hetvi_311/ros2_ws/install/wheelchair_isaac/share/wheelchair_isaac/meshes/base_link.stl" scale="0.001 0.001 0.001"/>
      </geometry>
      <material name="silver"/>
    </visual>
    <collision>
      <origin rpy="0 0 0" xyz="0 0 0"/>
      <geometry>
        <mesh filename="file:///home/hetvi_311/ros2_ws/install/wheelchair_isaac/share/wheelchair_isaac/meshes/base_link.stl" scale="0.001 0.001 0.001"/>
      </geometry>
    </collision>
  </link>
  <joint name="base_footprint_joint" type="fixed">
    <origin rpy="0 0 0" xyz="0 0 0.6"/>
    <parent link="base_footprint"/>
    <child link="base_link"/>
  </joint>
  <!-- IMU sensor link mounted at base_link center of mass -->
  <link name="imu_link">
    <inertial>
      <origin rpy="0 0 0" xyz="0 0 0"/>
      <mass value="0.01"/>
      <inertia ixx="1e-06" ixy="0" ixz="0" iyy="1e-06" iyz="0" izz="1e-06"/>
    </inertial>
    <visual>
      <origin rpy="0 0 0" xyz="0 0 0"/>
      <geometry>
        <box size="0.02 0.02 0.02"/>
      </geometry>
      <material name="silver"/>
    </visual>
    <collision>
      <origin rpy="0 0 0" xyz="0 0 0"/>
      <geometry>
        <box size="0.02 0.02 0.02"/>
      </geometry>
    </collision>
  </link>
  <joint name="imu_joint" type="fixed">
    <origin rpy="0 0 0" xyz="0.0 0.145 0.001"/>
    <parent link="base_link"/>
    <child link="imu_link"/>
  </joint>
  <link name="link_1_1">
    <inertial>
      <origin rpy="0 0 0" xyz="0.029999999999997057 -0.05767110693379862 -0.04228443270435201"/>
      <mass value="0.22006973891227524"/>
      <inertia ixx="0.000725" ixy="-0.0" ixz="-0.0" iyy="0.000301" iyz="-0.000324" izz="0.000441"/>
    </inertial>
    <visual>
      <origin rpy="0 0 0" xyz="0.269 -0.0798 0.054998"/>
      <geometry>
        <mesh filename="file:///home/hetvi_311/ros2_ws/install/wheelchair_isaac/share/wheelchair_isaac/meshes/link_1_1.stl" scale="0.001 0.001 0.001"/>
      </geometry>
      <material name="silver"/>
    </visual>
    <collision>
      <origin rpy="0 0 0" xyz="0.269 -0.0798 0.054998"/>
      <geometry>
        <mesh filename="file:///home/hetvi_311/ros2_ws/install/wheelchair_isaac/share/wheelchair_isaac/meshes/link_1_1.stl" scale="0.001 0.001 0.001"/>
      </geometry>
    </collision>
  </link>
  <!-- track_left_1 first (incorrect) definition removed - duplicate caused by Fusion 360 loop export bug -->
  <link name="left_wheel_1">
    <inertial>
      <origin rpy="0 0 0" xyz="0.07346889500880088 -2.88721996866137e-07 2.925630718242367e-07"/>
      <mass value="5.057776677564588"/>
      <inertia ixx="0.060549" ixy="-0.0" ixz="0.0" iyy="0.031987" iyz="0.0" izz="0.031987"/>
    </inertial>
    <visual>
      <origin rpy="0 0 0" xyz="0.284 -0.779417 0.322372"/>
      <geometry>
        <mesh filename="file:///home/hetvi_311/ros2_ws/install/wheelchair_isaac/share/wheelchair_isaac/meshes/left_wheel_1.stl" scale="0.001 0.001 0.001"/>
      </geometry>
      <material name="silver"/>
    </visual>
    <collision>
      <origin rpy="0 0 0" xyz="0.284 -0.779417 0.322372"/>
      <geometry>
        <mesh filename="file:///home/hetvi_311/ros2_ws/install/wheelchair_isaac/share/wheelchair_isaac/meshes/left_wheel_1.stl" scale="0.001 0.001 0.001"/>
      </geometry>
    </collision>
  </link>
  <link name="link_2_1">
    <inertial>
      <origin rpy="0 0 0" xyz="0.029999999999996974 -0.04053583985641179 0.00225104006153265"/>
      <mass value="0.15002189485578074"/>
      <inertia ixx="0.00025" ixy="0.0" ixz="-0.0" iyy="2.8e-05" iyz="2.1e-05" izz="0.000237"/>
    </inertial>
    <visual>
      <origin rpy="0 0 0" xyz="0.269 -0.185 0.179243"/>
      <geometry>
        <mesh filename="file:///home/hetvi_311/ros2_ws/install/wheelchair_isaac/share/wheelchair_isaac/meshes/link_2_1.stl" scale="0.001 0.001 0.001"/>
      </geometry>
      <material name="silver"/>
    </visual>
    <collision>
      <origin rpy="0 0 0" xyz="0.269 -0.185 0.179243"/>
      <geometry>
        <mesh filename="file:///home/hetvi_311/ros2_ws/install/wheelchair_isaac/share/wheelchair_isaac/meshes/link_2_1.stl" scale="0.001 0.001 0.001"/>
      </geometry>
    </collision>
  </link>
  <link name="link_1_right_1">
    <inertial>
      <origin rpy="0 0 0" xyz="-0.029999999999997085 -0.05767110693379844 -0.04228443270435229"/>
      <mass value="0.22006973891227521"/>
      <inertia ixx="0.000725" ixy="-0.0" ixz="0.0" iyy="0.000301" iyz="-0.000324" izz="0.000441"/>
    </inertial>
    <visual>
      <origin rpy="0 0 0" xyz="-0.269 -0.0798 0.054998"/>
      <geometry>
        <mesh filename="file:///home/hetvi_311/ros2_ws/install/wheelchair_isaac/share/wheelchair_isaac/meshes/link_1_right_1.stl" scale="0.001 0.001 0.001"/>
      </geometry>
      <material name="silver"/>
    </visual>
    <collision>
      <origin rpy="0 0 0" xyz="-0.269 -0.0798 0.054998"/>
      <geometry>
        <mesh filename="file:///home/hetvi_311/ros2_ws/install/wheelchair_isaac/share/wheelchair_isaac/meshes/link_1_right_1.stl" scale="0.001 0.001 0.001"/>
      </geometry>
    </collision>
  </link>
  <!-- track_right_1 first (incorrect) definition removed - duplicate caused by Fusion 360 loop export bug -->
  <link name="link_2_right_1">
    <inertial>
      <origin rpy="0 0 0" xyz="-0.029999999999996918 -0.040535839856411765 0.002251040061532622"/>
      <mass value="0.15002189485578074"/>
      <inertia ixx="0.00025" ixy="-0.0" ixz="0.0" iyy="2.8e-05" iyz="2.1e-05" izz="0.000237"/>
    </inertial>
    <visual>
      <origin rpy="0 0 0" xyz="-0.269 -0.185 0.179243"/>
      <geometry>
        <mesh filename="file:///home/hetvi_311/ros2_ws/install/wheelchair_isaac/share/wheelchair_isaac/meshes/link_2_right_1.stl" scale="0.001 0.001 0.001"/>
      </geometry>
      <material name="silver"/>
    </visual>
    <collision>
      <origin rpy="0 0 0" xyz="-0.269 -0.185 0.179243"/>
      <geometry>
        <mesh filename="file:///home/hetvi_311/ros2_ws/install/wheelchair_isaac/share/wheelchair_isaac/meshes/link_2_right_1.stl" scale="0.001 0.001 0.001"/>
      </geometry>
    </collision>
  </link>
  <link name="right_wheel_1">
    <inertial>
      <origin rpy="0 0 0" xyz="-0.07346889500880088 -2.887219975322708e-07 2.9256307310099317e-07"/>
      <mass value="5.057776677564578"/>
      <inertia ixx="0.060549" ixy="0.0" ixz="-0.0" iyy="0.031987" iyz="0.0" izz="0.031987"/>
    </inertial>
    <visual>
      <origin rpy="0 0 0" xyz="-0.284 -0.779417 0.322372"/>
      <geometry>
        <mesh filename="file:///home/hetvi_311/ros2_ws/install/wheelchair_isaac/share/wheelchair_isaac/meshes/right_wheel_1.stl" scale="0.001 0.001 0.001"/>
      </geometry>
      <material name="silver"/>
    </visual>
    <collision>
      <origin rpy="0 0 0" xyz="-0.284 -0.779417 0.322372"/>
      <geometry>
        <mesh filename="file:///home/hetvi_311/ros2_ws/install/wheelchair_isaac/share/wheelchair_isaac/meshes/right_wheel_1.stl" scale="0.001 0.001 0.001"/>
      </geometry>
    </collision>
  </link>
  <link name="back_seat_1">
    <inertial>
      <origin rpy="0 0 0" xyz="0.06983014601031234 0.0575986230963668 0.25115136347369765"/>
      <mass value="8.434452375183655"/>
      <inertia ixx="0.328288" ixy="8.5e-05" ixz="4.4e-05" iyy="0.418377" iyz="0.082281" izz="0.432904"/>
    </inertial>
    <visual>
      <origin rpy="0 0 0" xyz="0.069733 0.090525 -0.103815"/>
      <geometry>
        <mesh filename="file:///home/hetvi_311/ros2_ws/install/wheelchair_isaac/share/wheelchair_isaac/meshes/back_seat_1.stl" scale="0.001 0.001 0.001"/>
      </geometry>
      <material name="silver"/>
    </visual>
    <collision>
      <origin rpy="0 0 0" xyz="0.069733 0.090525 -0.103815"/>
      <geometry>
        <mesh filename="file:///home/hetvi_311/ros2_ws/install/wheelchair_isaac/share/wheelchair_isaac/meshes/back_seat_1.stl" scale="0.001 0.001 0.001"/>
      </geometry>
    </collision>
  </link>
  <link name="track_left_1">
    <inertial>
      <origin rpy="0 0 0" xyz="-0.019524250228306478 0.14117949011930947 -0.07567975004266825"/>
      <mass value="11.29429483652691"/>
      <inertia ixx="0.94688" ixy="-0.029005" ixz="-0.003106" iyy="0.150812" iyz="0.041131" izz="0.820835"/>
    </inertial>
    <visual>
      <origin rpy="0 0 0" xyz="0.224 -0.088296 0.167372"/>
      <geometry>
        <mesh filename="file:///home/hetvi_311/ros2_ws/install/wheelchair_isaac/share/wheelchair_isaac/meshes/track_left_1.stl" scale="0.001 0.001 0.001"/>
      </geometry>
      <material name="silver"/>
    </visual>
    <collision>
      <origin rpy="0 0 0" xyz="0.224 -0.088296 0.167372"/>
      <geometry>
        <mesh filename="file:///home/hetvi_311/ros2_ws/install/wheelchair_isaac/share/wheelchair_isaac/meshes/track_left_1.stl" scale="0.001 0.001 0.001"/>
      </geometry>
    </collision>
  </link>
  <link name="track_right_1">
    <inertial>
      <origin rpy="0 0 0" xyz="0.019524250884706162 0.14117948537533326 -0.07567974729896407"/>
      <mass value="11.294294709414698"/>
      <inertia ixx="0.94688" ixy="0.029005" ixz="0.003106" iyy="0.150812" iyz="0.041131" izz="0.820835"/>
    </inertial>
    <visual>
      <origin rpy="0 0 0" xyz="-0.224 -0.088296 0.167372"/>
      <geometry>
        <mesh filename="file:///home/hetvi_311/ros2_ws/install/wheelchair_isaac/share/wheelchair_isaac/meshes/track_right_1.stl" scale="0.001 0.001 0.001"/>
      </geometry>
      <material name="silver"/>
    </visual>
    <collision>
      <origin rpy="0 0 0" xyz="-0.224 -0.088296 0.167372"/>
      <geometry>
        <mesh filename="file:///home/hetvi_311/ros2_ws/install/wheelchair_isaac/share/wheelchair_isaac/meshes/track_right_1.stl" scale="0.001 0.001 0.001"/>
      </geometry>
    </collision>
  </link>
  <joint name="base_to_link1_left" type="revolute">
    <origin rpy="0 0 0" xyz="-0.269 0.0798 -0.054998"/>
    <parent link="base_link"/>
    <child link="link_1_1"/>
    <axis xyz="-1.0 -0.0 -0.0"/>
    <limit effort="100" lower="-1.5700" upper="0.0540" velocity="1.0"/>
  </joint>
  <!-- link1_to_track_left joint REMOVED from URDF tree (creates kinematic loop). -->
  <!-- This connection is closed in MuJoCo via <equality><connect> constraint. -->
  <!-- Pin hole on link_1_1 (relative to link_1_1 frame): pos="0.045 -0.113272 -0.099807" -->
  <joint name="wheel_left" type="continuous">
    <origin rpy="0 0 0" xyz="-0.06 0.691121 -0.155"/>
    <parent link="track_left_1"/>
    <child link="left_wheel_1"/>
    <axis xyz="-1.0 -0.0 -0.0"/>
  </joint>
  <joint name="base_to_link2_left" type="revolute">
    <origin rpy="0 0 0" xyz="-0.269 0.185 -0.179243"/>
    <parent link="base_link"/>
    <child link="link_2_1"/>
    <axis xyz="-1.0 -0.0 -0.0"/>
    <limit effort="100" lower="-1.5700" upper="0.3170" velocity="1.0"/>
  </joint>
  <joint name="base_to_link1_right" type="revolute">
    <origin rpy="0 0 0" xyz="0.269 0.0798 -0.054998"/>
    <parent link="base_link"/>
    <child link="link_1_right_1"/>
    <axis xyz="-1.0 0.0 0.0"/>
    <limit effort="100" lower="-1.5700" upper="0.0610" velocity="1.0"/>
  </joint>
  <!-- link1_to_track_right joint REMOVED from URDF tree (creates kinematic loop). -->
  <!-- This connection is closed in MuJoCo via <equality><connect> constraint. -->
  <!-- Pin hole on link_1_right_1 (relative to link_1_right_1 frame): pos="-0.045 -0.113272 -0.099807" -->
  <joint name="base_to_link2_right" type="revolute">
    <origin rpy="0 0 0" xyz="0.269 0.185 -0.179243"/>
    <parent link="base_link"/>
    <child link="link_2_right_1"/>
    <axis xyz="-1.0 0.0 0.0"/>
    <limit effort="100" lower="-1.5700" upper="0.3370" velocity="1.0"/>
  </joint>
  <joint name="wheel_right" type="continuous">
    <origin rpy="0 0 0" xyz="0.06 0.691121 -0.155"/>
    <parent link="track_right_1"/>
    <child link="right_wheel_1"/>
    <axis xyz="-1.0 0.0 0.0"/>
  </joint>
  <joint name="base_to_backSeat" type="revolute">
    <origin rpy="0 0 0" xyz="-0.069733 -0.090525 0.103815"/>
    <parent link="base_link"/>
    <child link="back_seat_1"/>
    <axis xyz="1.0 0.0 0.0"/>
    <limit effort="200" lower="0.0000" upper="0.0000" velocity="1.0"/>
  </joint>
  <joint name="Revolute 38" type="continuous">
    <origin rpy="0 0 0" xyz="0.045 -0.096704 0.011871"/>
    <parent link="link_2_1"/>
    <child link="track_left_1"/>
    <axis xyz="-1.0 -0.0 -0.0"/>
  </joint>
  <joint name="Revolute 39" type="continuous">
    <origin rpy="0 0 0" xyz="-0.045 -0.096704 0.011871"/>
    <parent link="link_2_right_1"/>
    <child link="track_right_1"/>
    <axis xyz="-1.0 0.0 0.0"/>
  </joint>
</robot>
