<?xml version="1.0" ?>
<robot name="robot" xmlns:xacro="http://www.ros.org/wiki/xacro">

<xacro:include filename="$(find wheelchair_isaac)/urdf/materials.xacro" />
<xacro:include filename="$(find wheelchair_isaac)/urdf/robot.trans" />
<xacro:include filename="$(find wheelchair_isaac)/urdf/robot.gazebo" />

<link name="base_footprint"/>

<link name="base_link">
  <inertial>
    <origin xyz="4.216737006355157e-05 0.14539775015650658 0.001317145519381857" rpy="0 0 0"/>
    <mass value="5.68537979998827"/>
    <inertia ixx="0.122934" iyy="0.179358" izz="0.285612" ixy="-3.1e-05" iyz="0.016444" ixz="6e-06"/>
  </inertial>
  <visual>
    <origin xyz="0 0 0" rpy="0 0 0"/>
    <geometry>
      <mesh filename="file://$(find wheelchair_isaac)/meshes/base_link.stl" scale="0.001 0.001 0.001"/>
    </geometry>
    <material name="silver"/>
  </visual>
  <collision>
    <origin xyz="0 0 0" rpy="0 0 0"/>
    <geometry>
      <mesh filename="file://$(find wheelchair_isaac)/meshes/base_link.stl" scale="0.001 0.001 0.001"/>
    </geometry>
  </collision>
</link>

<joint name="base_footprint_joint" type="fixed">
  <origin xyz="0 0 0.6" rpy="0 0 0"/>
  <parent link="base_footprint"/>
  <child link="base_link"/>
</joint>

<!-- IMU sensor link mounted at base_link center of mass -->
<link name="imu_link">
  <inertial>
    <origin xyz="0 0 0" rpy="0 0 0"/>
    <mass value="0.01"/>
    <inertia ixx="1e-06" iyy="1e-06" izz="1e-06" ixy="0" iyz="0" ixz="0"/>
  </inertial>
  <visual>
    <origin xyz="0 0 0" rpy="0 0 0"/>
    <geometry>
      <box size="0.02 0.02 0.02"/>
    </geometry>
    <material name="silver"/>
  </visual>
  <collision>
    <origin xyz="0 0 0" rpy="0 0 0"/>
    <geometry>
      <box size="0.02 0.02 0.02"/>
    </geometry>
  </collision>
</link>

<joint name="imu_joint" type="fixed">
  <origin xyz="0.0 0.145 0.001" rpy="0 0 0"/>
  <parent link="base_link"/>
  <child link="imu_link"/>
</joint>

<link name="link_1_1">
  <inertial>
    <origin xyz="0.029999999999997057 -0.05767110693379862 -0.04228443270435201" rpy="0 0 0"/>
    <mass value="0.22006973891227524"/>
    <inertia ixx="0.000725" iyy="0.000301" izz="0.000441" ixy="-0.0" iyz="-0.000324" ixz="-0.0"/>
  </inertial>
  <visual>
    <origin xyz="0.269 -0.0798 0.054998" rpy="0 0 0"/>
    <geometry>
      <mesh filename="file://$(find wheelchair_isaac)/meshes/link_1_1.stl" scale="0.001 0.001 0.001"/>
    </geometry>
    <material name="silver"/>
  </visual>
  <collision>
    <origin xyz="0.269 -0.0798 0.054998" rpy="0 0 0"/>
    <geometry>
      <mesh filename="file://$(find wheelchair_isaac)/meshes/link_1_1.stl" scale="0.001 0.001 0.001"/>
    </geometry>
  </collision>
</link>

<!-- track_left_1 first (incorrect) definition removed - duplicate caused by Fusion 360 loop export bug -->

<link name="left_wheel_1">
  <inertial>
    <origin xyz="0.07346889500880088 -2.88721996866137e-07 2.925630718242367e-07" rpy="0 0 0"/>
    <mass value="5.057776677564588"/>
    <inertia ixx="0.060549" iyy="0.031987" izz="0.031987" ixy="-0.0" iyz="0.0" ixz="0.0"/>
  </inertial>
  <visual>
    <origin xyz="0.284 -0.779417 0.322372" rpy="0 0 0"/>
    <geometry>
      <mesh filename="file://$(find wheelchair_isaac)/meshes/left_wheel_1.stl" scale="0.001 0.001 0.001"/>
    </geometry>
    <material name="silver"/>
  </visual>
  <collision>
    <origin xyz="0.284 -0.779417 0.322372" rpy="0 0 0"/>
    <geometry>
      <mesh filename="file://$(find wheelchair_isaac)/meshes/left_wheel_1.stl" scale="0.001 0.001 0.001"/>
    </geometry>
  </collision>
</link>

<link name="link_2_1">
  <inertial>
    <origin xyz="0.029999999999996974 -0.04053583985641179 0.00225104006153265" rpy="0 0 0"/>
    <mass value="0.15002189485578074"/>
    <inertia ixx="0.00025" iyy="2.8e-05" izz="0.000237" ixy="0.0" iyz="2.1e-05" ixz="-0.0"/>
  </inertial>
  <visual>
    <origin xyz="0.269 -0.185 0.179243" rpy="0 0 0"/>
    <geometry>
      <mesh filename="file://$(find wheelchair_isaac)/meshes/link_2_1.stl" scale="0.001 0.001 0.001"/>
    </geometry>
    <material name="silver"/>
  </visual>
  <collision>
    <origin xyz="0.269 -0.185 0.179243" rpy="0 0 0"/>
    <geometry>
      <mesh filename="file://$(find wheelchair_isaac)/meshes/link_2_1.stl" scale="0.001 0.001 0.001"/>
    </geometry>
  </collision>
</link>

<link name="link_1_right_1">
  <inertial>
    <origin xyz="-0.029999999999997085 -0.05767110693379844 -0.04228443270435229" rpy="0 0 0"/>
    <mass value="0.22006973891227521"/>
    <inertia ixx="0.000725" iyy="0.000301" izz="0.000441" ixy="-0.0" iyz="-0.000324" ixz="0.0"/>
  </inertial>
  <visual>
    <origin xyz="-0.269 -0.0798 0.054998" rpy="0 0 0"/>
    <geometry>
      <mesh filename="file://$(find wheelchair_isaac)/meshes/link_1_right_1.stl" scale="0.001 0.001 0.001"/>
    </geometry>
    <material name="silver"/>
  </visual>
  <collision>
    <origin xyz="-0.269 -0.0798 0.054998" rpy="0 0 0"/>
    <geometry>
      <mesh filename="file://$(find wheelchair_isaac)/meshes/link_1_right_1.stl" scale="0.001 0.001 0.001"/>
    </geometry>
  </collision>
</link>

<!-- track_right_1 first (incorrect) definition removed - duplicate caused by Fusion 360 loop export bug -->

<link name="link_2_right_1">
  <inertial>
    <origin xyz="-0.029999999999996918 -0.040535839856411765 0.002251040061532622" rpy="0 0 0"/>
    <mass value="0.15002189485578074"/>
    <inertia ixx="0.00025" iyy="2.8e-05" izz="0.000237" ixy="-0.0" iyz="2.1e-05" ixz="0.0"/>
  </inertial>
  <visual>
    <origin xyz="-0.269 -0.185 0.179243" rpy="0 0 0"/>
    <geometry>
      <mesh filename="file://$(find wheelchair_isaac)/meshes/link_2_right_1.stl" scale="0.001 0.001 0.001"/>
    </geometry>
    <material name="silver"/>
  </visual>
  <collision>
    <origin xyz="-0.269 -0.185 0.179243" rpy="0 0 0"/>
    <geometry>
      <mesh filename="file://$(find wheelchair_isaac)/meshes/link_2_right_1.stl" scale="0.001 0.001 0.001"/>
    </geometry>
  </collision>
</link>

<link name="right_wheel_1">
  <inertial>
    <origin xyz="-0.07346889500880088 -2.887219975322708e-07 2.9256307310099317e-07" rpy="0 0 0"/>
    <mass value="5.057776677564578"/>
    <inertia ixx="0.060549" iyy="0.031987" izz="0.031987" ixy="0.0" iyz="0.0" ixz="-0.0"/>
  </inertial>
  <visual>
    <origin xyz="-0.284 -0.779417 0.322372" rpy="0 0 0"/>
    <geometry>
      <mesh filename="file://$(find wheelchair_isaac)/meshes/right_wheel_1.stl" scale="0.001 0.001 0.001"/>
    </geometry>
    <material name="silver"/>
  </visual>
  <collision>
    <origin xyz="-0.284 -0.779417 0.322372" rpy="0 0 0"/>
    <geometry>
      <mesh filename="file://$(find wheelchair_isaac)/meshes/right_wheel_1.stl" scale="0.001 0.001 0.001"/>
    </geometry>
  </collision>
</link>

<link name="back_seat_1">
  <inertial>
    <origin xyz="0.06983014601031234 0.0575986230963668 0.25115136347369765" rpy="0 0 0"/>
    <mass value="8.434452375183655"/>
    <inertia ixx="0.328288" iyy="0.418377" izz="0.432904" ixy="8.5e-05" iyz="0.082281" ixz="4.4e-05"/>
  </inertial>
  <visual>
    <origin xyz="0.069733 0.090525 -0.103815" rpy="0 0 0"/>
    <geometry>
      <mesh filename="file://$(find wheelchair_isaac)/meshes/back_seat_1.stl" scale="0.001 0.001 0.001"/>
    </geometry>
    <material name="silver"/>
  </visual>
  <collision>
    <origin xyz="0.069733 0.090525 -0.103815" rpy="0 0 0"/>
    <geometry>
      <mesh filename="file://$(find wheelchair_isaac)/meshes/back_seat_1.stl" scale="0.001 0.001 0.001"/>
    </geometry>
  </collision>
</link>

<link name="track_left_1">
  <inertial>
    <origin xyz="-0.019524250228306478 0.14117949011930947 -0.07567975004266825" rpy="0 0 0"/>
    <mass value="11.29429483652691"/>
    <inertia ixx="0.94688" iyy="0.150812" izz="0.820835" ixy="-0.029005" iyz="0.041131" ixz="-0.003106"/>
  </inertial>
  <visual>
    <origin xyz="0.224 -0.088296 0.167372" rpy="0 0 0"/>
    <geometry>
      <mesh filename="file://$(find wheelchair_isaac)/meshes/track_left_1.stl" scale="0.001 0.001 0.001"/>
    </geometry>
    <material name="silver"/>
  </visual>
  <collision>
    <origin xyz="0.224 -0.088296 0.167372" rpy="0 0 0"/>
    <geometry>
      <mesh filename="file://$(find wheelchair_isaac)/meshes/track_left_1.stl" scale="0.001 0.001 0.001"/>
    </geometry>
  </collision>
</link>

<link name="track_right_1">
  <inertial>
    <origin xyz="0.019524250884706162 0.14117948537533326 -0.07567974729896407" rpy="0 0 0"/>
    <mass value="11.294294709414698"/>
    <inertia ixx="0.94688" iyy="0.150812" izz="0.820835" ixy="0.029005" iyz="0.041131" ixz="0.003106"/>
  </inertial>
  <visual>
    <origin xyz="-0.224 -0.088296 0.167372" rpy="0 0 0"/>
    <geometry>
      <mesh filename="file://$(find wheelchair_isaac)/meshes/track_right_1.stl" scale="0.001 0.001 0.001"/>
    </geometry>
    <material name="silver"/>
  </visual>
  <collision>
    <origin xyz="-0.224 -0.088296 0.167372" rpy="0 0 0"/>
    <geometry>
      <mesh filename="file://$(find wheelchair_isaac)/meshes/track_right_1.stl" scale="0.001 0.001 0.001"/>
    </geometry>
  </collision>
</link>

<joint name="base_to_link1_left" type="revolute">
  <origin xyz="-0.269 0.0798 -0.054998" rpy="0 0 0"/>
  <parent link="base_link"/>
  <child link="link_1_1"/>
  <axis xyz="-1.0 -0.0 -0.0"/>
  <limit lower="-1.5700" upper="0.0540" effort="100" velocity="1.0"/>
</joint>

<!-- link1_to_track_left joint REMOVED from URDF tree (creates kinematic loop). -->
<!-- This connection is closed in MuJoCo via <equality><connect> constraint. -->
<!-- Pin hole on link_1_1 (relative to link_1_1 frame): pos="0.045 -0.113272 -0.099807" -->

<joint name="wheel_left" type="continuous">
  <origin xyz="-0.06 0.691121 -0.155" rpy="0 0 0"/>
  <parent link="track_left_1"/>
  <child link="left_wheel_1"/>
  <axis xyz="-1.0 -0.0 -0.0"/>
</joint>

<joint name="base_to_link2_left" type="revolute">
  <origin xyz="-0.269 0.185 -0.179243" rpy="0 0 0"/>
  <parent link="base_link"/>
  <child link="link_2_1"/>
  <axis xyz="-1.0 -0.0 -0.0"/>
  <limit lower="-1.5700" upper="0.3170" effort="100" velocity="1.0"/>
</joint>

<joint name="base_to_link1_right" type="revolute">
  <origin xyz="0.269 0.0798 -0.054998" rpy="0 0 0"/>
  <parent link="base_link"/>
  <child link="link_1_right_1"/>
  <axis xyz="-1.0 0.0 0.0"/>
  <limit lower="-1.5700" upper="0.0610" effort="100" velocity="1.0"/>
</joint>

<!-- link1_to_track_right joint REMOVED from URDF tree (creates kinematic loop). -->
<!-- This connection is closed in MuJoCo via <equality><connect> constraint. -->
<!-- Pin hole on link_1_right_1 (relative to link_1_right_1 frame): pos="-0.045 -0.113272 -0.099807" -->

<joint name="base_to_link2_right" type="revolute">
  <origin xyz="0.269 0.185 -0.179243" rpy="0 0 0"/>
  <parent link="base_link"/>
  <child link="link_2_right_1"/>
  <axis xyz="-1.0 0.0 0.0"/>
  <limit lower="-1.5700" upper="0.3370" effort="100" velocity="1.0"/>
</joint>

<joint name="wheel_right" type="continuous">
  <origin xyz="0.06 0.691121 -0.155" rpy="0 0 0"/>
  <parent link="track_right_1"/>
  <child link="right_wheel_1"/>
  <axis xyz="-1.0 0.0 0.0"/>
</joint>

<joint name="base_to_backSeat" type="revolute">
  <origin xyz="-0.069733 -0.090525 0.103815" rpy="0 0 0"/>
  <parent link="base_link"/>
  <child link="back_seat_1"/>
  <axis xyz="1.0 0.0 0.0"/>
  <limit lower="0.0000" upper="0.0000" effort="200" velocity="1.0"/>
</joint>

<joint name="Revolute 38" type="continuous">
  <origin xyz="0.045 -0.096704 0.011871" rpy="0 0 0"/>
  <parent link="link_2_1"/>
  <child link="track_left_1"/>
  <axis xyz="-1.0 -0.0 -0.0"/>
</joint>

<joint name="Revolute 39" type="continuous">
  <origin xyz="-0.045 -0.096704 0.011871" rpy="0 0 0"/>
  <parent link="link_2_right_1"/>
  <child link="track_right_1"/>
  <axis xyz="-1.0 0.0 0.0"/>
</joint>

</robot>

